Workbook

Sheet 累積半月報
A1: 縣市 | B1: 業者 | C1: 代租代管 | I1: 包租包管 | P1: 總計
C2: 媒合費 | D2: 代管費 | E2: 修繕費 | F2: 公證費 | G2: 租補費 | H2: 合計 | I2: 開發費 | J2: 包管費 | K2: 修繕費 | L2: 保險費 | M2: 公證費 | N2: 租補費 | O2: 合計
A3: 哪個縣市 | B3: 業者名稱 | C3: ='代租 '!#REF! -> #REF! | D3: ='代租 '!#REF! -> #REF! | E3: ='代租 '!#REF! -> #REF! | F3: ='代租 '!#REF! -> #REF! | G3: ='代租 '!#REF! -> #REF! | H3: =SUM(C3:G3) -> #REF! | I3: ='包租 '!#REF! -> #REF! | J3: ='包租 '!#REF! -> #REF! | K3: ='包租 '!#REF! -> #REF! | L3: ='包租 '!#REF! -> #REF! | M3: ='包租 '!#REF! -> #REF! | N3: ='包租 '!#REF! -> #REF! | O3: =SUM(I3:N3) -> #REF! | P3: =SUM(H3:H8,O3:O8) -> #REF!
C4: ='代租 '!#REF! -> #REF! | D4: ='代租 '!#REF! -> #REF! | E4: ='代租 '!#REF! -> #REF! | F4: ='代租 '!#REF! -> #REF! | G4: ='代租 '!#REF! -> #REF! | H4: =SUM(C4:G4) -> #REF! | I4: ='包租 '!#REF! -> #REF! | J4: ='包租 '!#REF! -> #REF! | K4: ='包租 '!#REF! -> #REF! | L4: ='包租 '!#REF! -> #REF! | M4: ='包租 '!#REF! -> #REF! | N4: ='包租 '!#REF! -> #REF! | O4: =SUM(I4:N4) -> #REF!
C5: ='代租 '!#REF! -> #REF! | D5: ='代租 '!#REF! -> #REF! | E5: ='代租 '!#REF! -> #REF! | F5: ='代租 '!#REF! -> #REF! | G5: ='代租 '!#REF! -> #REF! | H5: =SUM(C5:G5) -> #REF! | I5: ='包租 '!#REF! -> #REF! | J5: ='包租 '!#REF! -> #REF! | K5: ='包租 '!#REF! -> #REF! | L5: ='包租 '!#REF! -> #REF! | M5: ='包租 '!#REF! -> #REF! | N5: ='包租 '!#REF! -> #REF! | O5: =SUM(I5:N5) -> #REF!
C6: ='代租 '!#REF! -> #REF! | D6: ='代租 '!#REF! -> #REF! | E6: ='代租 '!#REF! -> #REF! | F6: ='代租 '!#REF! -> #REF! | G6: ='代租 '!#REF! -> #REF! | H6: =SUM(C6:G6) -> #REF! | I6: =SUM('包租 '!#REF!) -> #REF! | J6: =SUM('包租 '!#REF!) -> #REF! | K6: =SUM('包租 '!#REF!) -> #REF! | L6: =SUM('包租 '!#REF!) -> #REF! | M6: =SUM('包租 '!#REF!) -> #REF! | N6: =SUM('包租 '!#REF!) -> #REF! | O6: =SUM(I6:N6) -> #REF!
C7: =SUM('代租 '!#REF!) -> #REF! | D7: ='代租 '!#REF! -> #REF! | E7: ='代租 '!#REF! -> #REF! | F7: ='代租 '!#REF! -> #REF! | G7: ='代租 '!#REF! -> #REF! | H7: =SUM(C7:G7) -> #REF! | I7: ='包租 '!#REF! -> #REF! | J7: ='包租 '!#REF! -> #REF! | K7: ='包租 '!#REF! -> #REF! | L7: ='包租 '!#REF! -> #REF! | M7: ='包租 '!#REF! -> #REF! | N7: ='包租 '!#REF! -> #REF! | O7: =SUM(I7:N7) -> #REF!
C8: ='代租 '!Q255 -> 808000 | D8: ='代租 '!S256 -> 2503200 | E8: ='代租 '!CZ256 -> 468860 | F8: ='代租 '!EU256 -> 87750 | G8: ='代租 '!FA256 -> 0 | H8: =SUM(C8:G8) -> 3867810 | I8: ='包租 '!S49 -> 36000 | J8: ='包租 '!AA50 -> 96000 | K8: ='包租 '!DB50 -> 10000 | L8: ='包租 '!DK49 -> 2766 | M8: ='包租 '!FD50 -> 6500 | N8: ='包租 '!FJ50 -> 0 | O8: =SUM(I8:N8) -> 151266

Sheet 半月報
A1: 業者 | B1: 出租人補助費(表單4) | E1: 承租人補助費(表單7) | G1: 服務費（表單8） | L1: 各業者服務費(不含公證費)
B2: 居家安全保險費 | C2: 公證費 | D2: 修繕費 | E2: 公證費 | F2: 租金補助 | G2: 公證費 | H2: 開發費 | I2: 包管費 | J2: 媒合費 | K2: 代管費
A3: 業者名稱 | D3: =SUM('包租 '!#REF!) -> #REF! | E3: =SUM('包租 '!#REF!) -> #REF! | H3: =SUM('包租 '!#REF!) -> #REF! | I3: =SUM('包租 '!#REF!) -> #REF! | J3: =SUM('代租 '!#REF!) -> #REF! | K3: =SUM('代租 '!#REF!) -> #REF! | L3: =SUM(H3:K3) -> #REF!
L4: =SUM(H4:K4) -> 0
L5: =SUM(H5:K5) -> 0
E6: =SUM('包租 '!#REF!) -> #REF! | F6: =SUM('包租 '!#REF!) -> #REF! | H6: =SUM('包租 '!#REF!) -> #REF! | I6: =SUM('包租 '!#REF!) -> #REF! | J6: =SUM('代租 '!#REF!) -> #REF! | K6: =SUM('代租 '!#REF!) -> #REF! | L6: =SUM(H6:K6) -> #REF!
E7: =SUM('包租 '!#REF!) -> #REF! | F7: ='包租 '!#REF! -> #REF! | H7: =SUM('包租 '!#REF!) -> #REF! | I7: ='包租 '!#REF! -> #REF! | J7: ='代租 '!#REF! -> #REF! | K7: ='代租 '!#REF! -> #REF! | L7: =SUM(H7:K7) -> #REF!
E8: ='包租 '!FD52 -> #REF! | F8: ='包租 '!FJ52 -> 0 | H8: ='包租 '!S51 -> #REF! | I8: ='包租 '!AA51 -> #REF! | J8: ='代租 '!Q257 -> 8000 | K8: ='代租 '!S257 -> 4800 | L8: =SUM(H8:K8) -> #REF!
A9: 總計 | B9: =SUM(B3:B8) -> 0 | C9: =SUM(C3:C8) -> 0 | D9: =SUM(D3:D8) -> #REF! | E9: =SUM(E3:E8) -> #REF! | F9: =SUM(F3:F8) -> #REF! | G9: =SUM(G3:G8) -> 0 | H9: =SUM(H3:H8) -> #REF! | I9: =SUM(I3:I8) -> #REF! | ... L9: =SUM(L3:L8) -> #REF!
C10: 公證費合計 | E10: =C9+E9 -> #REF! | J10: 總計撥付款項 | L10: =SUM(B9:K9) -> #REF!

Sheet 代租 
A1: 序號 | B1: 業者 | G1: 租賃契約資料 | Q1: 業者 | CM1: 房東 | EA1: 房客
D2: 媒合編號 | E2: 異動原因 (例：自然終止、中止租約) | F2: 自然/中止租約日期(xxx-xx-xx) | G2: 房屋座落地址 | H2: 行政區 | I2: 地段 | J2: 地號(xxxx-xxxx/xxxx-xxxx) | K2: 建號(xxxxx-xxxx) | L2: 謄本面積 (m²) | M2: 租賃範圍 (全部/部分) | N2: 租約起日(xxx/xx/xx) | O2: 租約訖日(xxx/xx/xx) | P2: 簽約租金 | Q2: 媒合費 | S2: 第一年代管費 | AQ2: 第二年代管費 | BO2: 第三年代管費 | CM2: 房東姓名(代表人) | CN2: 基本資料 | CR2: 房東姓名(共有人/共有人) | CS2: 身分證(共有人/共有人) | CT2: 公證費(1) | CV2: 公證費(2) | CX2: 公證費(3) | CZ2: 修繕費 | EA2: 代表人匯款資料 | EE2: 代表人家庭成員 | EN2: 共住人/共住人匯款資料 | ER2: 共住人家庭成員 | EU2: 公證費(1) | EW2: 公證費(2) | EY2: 公證費(3) | FA2: 第一年租金補貼 | FY2: 第二年租金補貼 | GW2: 第三年租金補貼
Q3: 媒合費 | R3: 撥款日期(xxx-xx-xx) | S3: 第一期 | U3: 第二期 | W3: 第三期 | Y3: 第四期 | AA3: 第五期 | AC3: 第六期 | AE3: 第七期 | AG3: 第八期 | AI3: 第九期 | AK3: 第十期 | AM3: 第十一期 | AO3: 第十二期 | AQ3: 第十三期 | AS3: 第十四期 | AU3: 第十五期 | AW3: 第十六期 | AY3: 第十七期 | BA3: 第十八期 | BC3: 第十九期 | BE3: 第二十期 | BG3: 第二十一期 | BI3: 第二十二期 | BK3: 第二十三期 | BM3: 第二十四期 | BO3: 第二十五期 | BQ3: 第二十六期 | BS3: 第二十七期 | BU3: 第二十八期 | BW3: 第二十九期 | BY3: 第三十期 | CA3: 第三十一期 | CC3: 第三十二期 | CE3: 第三十三期 | CG3: 第三十四期 | CI3: 第三十五期 | CK3: 第三十六期 | CN3: 身分證(代表人) | CO3: 銀行代碼 (7碼) | CP3: 帳號 | CQ3: 通訊地址 | CT3: 公證費 | CU3: 撥款日期(xxx-xx-xx) | CV3: 公證費 | CW3: 撥款日期 | CX3: 公證費 | CY3: 撥款日期 | CZ3: 第一年(1) | DB3: 第一年(2) | DD3: 第一年(3) | DF3: 第一年(4) | DH3: 修繕費餘額 | DI3: 第二年(1) | DK3: 第二年(2) | DM3: 第二年(3) | DO3: 第二年(4) | DQ3: 修繕費餘額 | DR3: 第三年(1) | DT3: 第三年(2) | DV3: 第三年(3) | DX3: 第三年(4) | DZ3: 修繕費餘額 | EA3: 房客姓名 | EB3: 身分證 | EC3: 銀行代碼 (7碼) | ED3: 帳號 | EE3: 親屬姓名(1) | EH3: 親屬姓名(2) | EK3: 親屬姓名(3) | EN3: 房客姓名 | EO3: 身分證 | EP3: 銀行代碼 (7碼) | EQ3: 帳號 | ER3: 親屬姓名 | EU3: 公證費 | EV3: 撥款日期(xxx-xx-xx) | EW3: 公證費 | EX3: 撥款日期 | EY3: 公證費 | EZ3: 撥款日期 | FA3: 第一期 | FC3: 第二期 | FE3: 第三期 | FG3: 第四期 | FI3: 第五期 | FK3: 第六期 | FM3: 第七期 | FO3: 第八期 | FQ3: 第九期 | FS3: 第十期 | FU3: 第十一期 | FW3: 第十二期 | FY3: 第十三期 | GA3: 第十四期 | GC3: 第十五期 | GE3: 第十六期 | GG3: 第十七期 | GI3: 第十八期 | GK3: 第十九期 | GM3: 第二十期 | GO3: 第二十一期 | GQ3: 第二十二期 | GS3: 第二十三期 | GU3: 第二十四期 | GW3: 第二十五期 | GY3: 第二十六期 | HA3: 第二十七期 | HC3: 第二十八期 | HE3: 第二十九期 | HG3: 第三十期 | HI3: 第三十一期 | HK3: 第三十二期 | HM3: 第三十三期 | HO3: 第三十四期 | HQ3: 第三十五期 | HS3: 第三十六期
C4: 滅火器 | S4: 代管費 | T4: 撥款日期(xxx-xx-xx) | U4: 代管費 | V4: 撥款日期(xxx-xx-xx) | W4: 代管費 | X4: 撥款日期(xxx-xx-xx) | Y4: 代管費 | Z4: 撥款日期(xxx-xx-xx) | AA4: 代管費 | AB4: 撥款日期(xxx-xx-xx) | AC4: 代管費 | AD4: 撥款日期(xxx-xx-xx) | AE4: 代管費 | AF4: 撥款日期(xxx-xx-xx) | AG4: 代管費 | AH4: 撥款日期(xxx-xx-xx) | AI4: 代管費 | AJ4: 撥款日期(xxx-xx-xx) | AK4: 代管費 | AL4: 撥款日期(xxx-xx-xx) | AM4: 代管費 | AN4: 撥款日期(xxx-xx-xx) | AO4: 代管費 | AP4: 撥款日期(xxx-xx-xx) | AQ4: 代管費 | AR4: 撥款日期 | AS4: 代管費 | AT4: 撥款日期 | AU4: 代管費 | AV4: 撥款日期 | AW4: 代管費 | AX4: 撥款日期 | AY4: 代管費 | AZ4: 撥款日期 | BA4: 代管費 | BB4: 撥款日期 | BC4: 代管費 | BD4: 撥款日期 | BE4: 代管費 | BF4: 撥款日期 | BG4: 代管費 | BH4: 撥款日期 | BI4: 代管費 | BJ4: 撥款日期 | BK4: 代管費 | BL4: 撥款日期 | BM4: 代管費 | BN4: 撥款日期 | BO4: 代管費 | BP4: 撥款日期 | BQ4: 代管費 | BR4: 撥款日期 | BS4: 代管費 | BT4: 撥款日期 | BU4: 代管費 | BV4: 撥款日期 | BW4: 代管費 | BX4: 撥款日期 | BY4: 代管費 | BZ4: 撥款日期 | CA4: 代管費 | CB4: 撥款日期 | CC4: 代管費 | CD4: 撥款日期 | CE4: 代管費 | CF4: 撥款日期 | CG4: 代管費 | CH4: 撥款日期 | CI4: 代管費 | CJ4: 撥款日期 | CK4: 代管費 | CL4: 撥款日期 | CZ4: 修繕費 | DA4: 撥款日期(xxx-xx-xx) | DB4: 修繕費 | DC4: 撥款日期(xxx-xx-xx) | DD4: 修繕費 | DE4: 撥款日期(xxx-xx-xx) | DF4: 修繕費 | DG4: 撥款日期(xxx-xx-xx) | DI4: 修繕費 | DJ4: 撥款日期 | DK4: 修繕費 | DL4: 撥款日期 | DM4: 修繕費 | DN4: 撥款日期 | DO4: 修繕費 | DP4: 撥款日期 | DR4: 修繕費 | DS4: 撥款日期 | DT4: 修繕費 | DU4: 撥款日期 | DV4: 修繕費 | DW4: 撥款日期 | DX4: 修繕費 | DY4: 撥款日期 | EE4: 姓名 | EF4: 身分證 | EG4: 與代表人關係 | EH4: 姓名 | EI4: 身分證 | EJ4: 與代表人關係 | EK4: 姓名 | EL4: 身分證 | EM4: 與代表人關係 | ER4: 姓名 | ES4: 身分證 | ET4: 與代表人關係 | FA4: 租金補貼 | FB4: 撥款日期(xxx-xx-xx) | FC4: 租金補貼 | FD4: 撥款日期(xxx-xx-xx) | FE4: 租金補貼 | FF4: 撥款日期(xxx-xx-xx) | FG4: 租金補貼 | FH4: 撥款日期(xxx-xx-xx) | FI4: 租金補貼 | FJ4: 撥款日期(xxx-xx-xx) | FK4: 租金補貼 | FL4: 撥款日期(xxx-xx-xx) | FM4: 租金補貼 | FN4: 撥款日期(xxx-xx-xx) | FO4: 租金補貼 | FP4: 撥款日期(xxx-xx-xx) | FQ4: 租金補貼 | FR4: 撥款日期(xxx-xx-xx) | FS4: 租金補貼 | FT4: 撥款日期(xxx-xx-xx) | FU4: 租金補貼 | FV4: 撥款日期(xxx-xx-xx) | FW4: 租金補貼 | FX4: 撥款日期(xxx-xx-xx) | FY4: 租金補貼 | FZ4: 撥款日期 | GA4: 租金補貼 | GB4: 撥款日期 | GC4: 租金補貼 | GD4: 撥款日期 | GE4: 租金補貼 | GF4: 撥款日期 | GG4: 租金補貼 | GH4: 撥款日期 | GI4: 租金補貼 | GJ4: 撥款日期 | GK4: 租金補貼 | GL4: 撥款日期 | GM4: 租金補貼 | GN4: 撥款日期 | GO4: 租金補貼 | GP4: 撥款日期 | GQ4: 租金補貼 | GR4: 撥款日期 | GS4: 租金補貼 | GT4: 撥款日期 | GU4: 租金補貼 | GV4: 撥款日期 | GW4: 租金補貼 | GX4: 撥款日期 | GY4: 租金補貼 | GZ4: 撥款日期 | HA4: 租金補貼 | HB4: 撥款日期 | HC4: 租金補貼 | HD4: 撥款日期 | HE4: 租金補貼 | HF4: 撥款日期 | HG4: 租金補貼 | HH4: 撥款日期 | HI4: 租金補貼 | HJ4: 撥款日期 | HK4: 租金補貼 | HL4: 撥款日期 | HM4: 租金補貼 | HN4: 撥款日期 | HO4: 租金補貼 | HP4: 撥款日期 | HQ4: 租金補貼 | HR4: 撥款日期 | HS4: 租金補貼 | HT4: 撥款日期
A5: =ROW()-4 -> 1 | B5: 易居 | D5: 易居A2M10400002 | E5: 終止租約 | F5: 113-07-05 | G5: 臺北市南港區中南街50號3樓 | H5: =MID(G5,4,3) -> 南港區 | I5: 南港段二小段 | J5: 0769-0001/0770-0000 | K5: 0113-000 | L5: 111.75 | M5: 全部 | N5: =O5-365 -> 45113 | O5: 45478 | P5: 33000 | Q5: 16000 | R5: 112-08-31 | S5: 2400 | T5: 112-08-31 | U5: 2400 | V5: 112-09-15 | W5: 2400 | X5: 112-10-16 | Y5: 2400 | Z5: 112-11-15 | AA5: 2400 | AB5: 112-12-15 | AC5: 2400 | AD5: 112-01-15 | AE5: 2400 | AF5: 113-02-29 | AG5: 2400 | AH5: 113-03-29 | AI5: 2400 | AJ5: 113-04-30 | AK5: 2400 | AL5: 113-05-15 | AM5: 2400 | AN5: 113-06-14 | AO5: 2400 | AP5: 113-07-15 | CM5: 廖德璋 | CN5: F120557935 | CO5: 1180774 | CP5: 07745000091485 | CQ5: 新北市汐止區國興街22巷4號 | CT5: 4500 | CU5: 112-08-31 | CZ5: 1428 | DA5: 112-08-31 | DB5: 4200 | DC5: 113-02-29 | DH5: =10000-DF5-DD5-DB5-CZ5 -> 4372 | EA5: 李奕宏 | EB5: R124795707 | EC5: 0076010 | ED5: 60168114105
A6: =ROW()-4 -> 2 | B6: 易居 | D6: 易居A2M10400007 | E6: 續約 | G6: 臺北市信義區吳興街361巷23弄3號4樓 | H6: =MID(G6,4,3) -> 信義區 | I6: 吳興段一小段 | J6: 0131-0000 | K6: 00403-000 | L6: 71.82 | M6: 全部 | N6: =O6-365 -> 45122 | O6: 45487 | P6: 20000 | Q6: 16000 | R6: 112-08-31 | S6: 2400 | T6: 112-08-31 | U6: 2400 | V6: 112-09-15 | W6: 2400 | X6: 112-10-16 | Y6: 2400 | Z6: 112-11-15 | AA6: 2400 | AB6: 112-12-15 | AC6: 2400 | AD6: 112-01-15 | AE6: 2400 | AF6: 113-02-29 | AG6: 2400 | AH6: 113-03-29 | AI6: 2400 | AJ6: 113-04-30 | AK6: 2400 | AL6: 113-05-15 | AM6: 2400 | AN6: 113-06-14 | AO6: 2400 | AP6: 113-07-15 | CM6: 蘇范竹英 | CN6: J201653373 | CO6: 1300156 | CP6: 01500400000037 | CQ6: 新竹縣芎林鄉文山路646巷2號 | DH6: =10000-DF6-DD6-DB6-CZ6 -> 10000 | EA6: 劉月萍 | EB6: J220804998 | EC6: 7000021 | ED6: 00613390629114
A7: =ROW()-4 -> 3 | B7: 易居 | D7: 易居A2M10400011 | E7: 續約 | G7: 臺北市內湖區康樂街48巷25號5樓 | H7: =MID(G7,4,3) -> 內湖區 | I7: 東湖段一小段 | J7: 0022-0023 | K7: 02793-000 | L7: 108.46 | M7: 全部 | N7: =O7-365 -> 45126 | O7: 45491 | P7: 23000 | Q7: 8000 | R7: 112-09-15 | S7: 2400 | T7: 112-09-15 | U7: 2400 | V7: 112-09-28 | W7: 2400 | X7: 112-10-31 | Y7: 2400 | Z7: 112-11-30 | AA7: 2400 | AB7: 112-12-29 | AC7: 2400 | AD7: 112-01-15 | AE7: 2400 | AF7: 113-02-29 | AG7: 2400 | AH7: 113-03-29 | AI7: 2400 | AJ7: 113-04-30 | AK7: 2400 | AL7: 113-05-15 | AM7: 2400 | AN7: 113-06-28 | AO7: 2400 | AP7: 113-07-31 | CM7: 鄭婷華 | CN7: D221519733 | CO7: 0130730 | CP7: 073051008232 | CQ7: 臺北市內湖區內湖路一段591巷11弄4號5樓 | CZ7: 6930 | DA7: 113-01-31 | DB7: 3070 | DC7: 113-07-31 | DH7: =10000-DF7-DD7-DB7-CZ7 -> 0 | EA7: 陳奕臻 | EB7: F221559668 | EC7: 7000021 | ED7: 00019110143701 | EE7: 范煜祥 | EF7: A129343610 | EG7: 長子 | EH7: 范明煌 | EI7: A126022972 | EJ7: 次子 | EK7: 范勻瑄 | EL7: A232119120 | EM7: 孫女
A8: =ROW()-4 -> 4 | B8: 易居 | D8: 易居A2M10400013 | E8: 續約 | G8: 臺北市內湖區內湖路三段59巷7弄3號4樓 | H8: =MID(G8,4,3) -> 內湖區 | I8: 碧湖段一小段 | J8: 0338-0000 | K8: 01044-000 | L8: 85.32 | M8: 全部 | N8: =O8-365 -> 45139 | O8: 45504 | P8: 20000 | Q8: 8000 | R8: 112-09-15 | S8: 2400 | T8: 112-09-15 | U8: 2400 | V8: 112-10-16 | W8: 2400 | X8: 112-11-15 | Y8: 2400 | Z8: 112-12-15 | AA8: 2400 | AB8: 112-01-15 | AC8: 2400 | AD8: 113-02-29 | AE8: 2400 | AF8: 113-03-29 | AG8: 2400 | AH8: 113-04-30 | AI8: 2400 | AJ8: 113-05-15 | AK8: 2400 | AL8: 113-06-14 | AM8: 2400 | AN8: 113-07-15 | AO8: 2400 | AP8: 113-09-20 | CM8: 鍾問晟 | CN8: H122018264 | CO8: 8220141 | CP8: 141540046580 | CQ8: 臺北市中正區羅斯福路一段99號4樓 | DH8: =10000-DF8-DD8-DB8-CZ8 -> 10000 | EA8: 陳凱雲 | EB8: A224169803 | EC8: 8080129 | ED8: 0129968207878
A9: =ROW()-4 -> 5 | B9: 易居 | D9: 易居A2M10400014 | E9: 續約 | G9: 臺北市中山區新生北路三段34號9樓之5 | H9: =MID(G9,4,3) -> 中山區 | I9: 德惠段四小段 | J9: 0570-0000 | K9: 04194-000 | L9: 46.27 | M9: 全部 | N9: =O9-365 -> 45139 | O9: 45504 | P9: 15000 | Q9: 16000 | R9: 112-09-28 | S9: 2400 | T9: 112-09-28 | U9: 2400 | V9: 112-10-16 | W9: 2400 | X9: 112-11-15 | Y9: 2400 | Z9: 112-12-15 | AA9: 2400 | AB9: 112-01-15 | AC9: 2400 | AD9: 113-02-29 | AE9: 2400 | AF9: 113-03-29 | AG9: 2400 | AH9: 113-04-30 | AI9: 2400 | AJ9: 113-05-15 | AK9: 2400 | AL9: 113-06-14 | AM9: 2400 | AN9: 113-07-15 | AO9: 2400 | AP9: 113-09-20 | CM9: 劉麗珠 | CN9: R222185652 | CO9: 8080211 | CP9: 0211466021130 | CQ9: 臺北市內湖區內湖路二段254號3樓 | DH9: =10000-DF9-DD9-DB9-CZ9 -> 10000 | EA9: 游惠茹 | EB9: A220230641 | EC9: 8220060 | ED9: 060536968601
A10: =ROW()-4 -> 6 | B10: 易居 | D10: 易居A2M10400027 | E10: 續約 | G10: 臺北市大安區敦化南路二段81巷65弄6號3樓 | H10: =MID(G10,4,3) -> 大安區 | I10: 通化段五小段 | J10: 0295-0000 | K10: 00287-000 | L10: 99.64 | M10: 全部 | N10: =O10-365 -> 45170 | O10: 45535 | P10: 35000 | Q10: 4000 | R10: 112-10-16 | S10: 2400 | T10: 112-10-16 | U10: 2400 | V10: 112-11-15 | W10: 2400 | X10: 112-12-15 | Y10: 2400 | Z10: 112-01-15 | AA10: 2400 | AB10: 113-02-29 | AC10: 2400 | AD10: 113-03-29 | AE10: 2400 | AF10: 113-04-30 | AG10: 2400 | AH10: 113-05-15 | AI10: 2400 | AJ10: 113-06-14 | AK10: 2400 | AL10: 113-07-15 | AM10: 2400 | AN10: 113-09-20 | AO10: 2400 | AP10: 113-10-20 | CM10: 姚秋娟 | CN10: F222821494 | CO10: 8080532 | CP10: 0532979092588 | CQ10: 新北市淡水區新市一路一段99巷29號14樓 | CT10: 4500 | CU10: 112-10-16 | CZ10: 10000 | DA10: 113-02-15 | DH10: =10000-DF10-DD10-DB10-CZ10 -> 0 | EA10: 鄭麗英 | EB10: A222036221 | EC10: 7000021 | ED10: 00010100973558 | EE10: 王思涵 | EF10: A224335594 | EG10: 長女 | EH10: 王思淳 | EI10: A225951387 | EJ10: 參女 | EK10: 黃婕凌 | EL10: E227335090 | EM10: 孫女
A11: =ROW()-4 -> 7 | B11: 易居 | D11: 易居A2M10400030 | E11: 中止租約 | F11: 113-07-31 | G11: 臺北市士林區葫蘆街23巷14號 | H11: =MID(G11,4,3) -> 士林區 | I11: 海光段三小段 | J11: 0402-0000 | K11: 30860-000 | L11: 71.81 | M11: 全部 | N11: =O11-365 -> 45170 | O11: 45535 | P11: 15000 | Q11: 16000 | R11: 112-10-16 | S11: 2400 | T11: 112-10-16 | U11: 2400 | V11: 112-11-15 | W11: 2400 | X11: 112-12-15 | Y11: 2400 | Z11: 112-01-15 | AA11: 2400 | AB11: 113-02-29 | AC11: 2400 | AD11: 113-03-29 | AE11: 2400 | AF11: 113-04-30 | AG11: 2400 | AH11: 113-05-15 | AI11: 2400 | AJ11: 113-06-14 | AK11: 2400 | AL11: 113-07-15 | AM11: 2400 | AN11: 113-09-20 | AO11: - | AP11: - | CM11: 蕭證元 | CN11: A124073766 | CO11: 8120171 | CP11: 20171590008234 | CQ11: 臺北市士林區葫蘆街23巷14號 | CZ11: 850 | DA11: 112-10-16 | DB11: 9150 | DC11: 113-10-20 | DH11: =10000-DF11-DD11-DB11-CZ11 -> 0 | EA11: 張嘉財 | EB11: U120552889 | EC11: 8220624 | ED11: 624530201959
A12: =ROW()-4 -> 8 | B12: 易居 | D12: 易居A2M10400037 | E12: 自然中止 | F12: 113-09-14 | G12: 臺北市北投區西安街一段187號3樓 | H12: =MID(G12,4,3) -> 北投區 | I12: 文林段三小段 | J12: 0271-0000 | K12: 33722-000 | L12: 58.92 | M12: 全部 | N12: =O12-365 -> 45184 | O12: 45549 | P12: 10000 | Q12: 16000 | R12: 112-11-15 | S12: 2400 | T12: 112-11-15 | U12: 2400 | V12: 112-11-30 | W12: 2400 | X12: 112-12-15 | Y12: 2400 | Z12: 112-01-15 | AA12: 2400 | AB12: 113-02-29 | AC12: 2400 | AD12: 113-03-29 | AE12: 2400 | AF12: 113-04-30 | AG12: 2400 | AH12: 113-05-15 | AI12: 2400 | AJ12: 113-06-14 | AK12: 2400 | AL12: 113-07-15 | AM12: 2400 | AN12: 113-09-20 | AO12: 2400 | AP12: 113-10-20 | CM12: 陳凱倫 | CN12: A224443751 | CO12: 0124209 | CP12: 00420168168607 | CQ12: 臺北市北投區石牌里7鄰西安街一段187號3樓 | CZ12: 10000 | DA12: 113-09-20 | DH12: =10000-DF12-DD12-DB12-CZ12 -> 0 | EA12: 李采庭 | EB12: Q222595399 | EC12: 0130187 | ED12: 018505511545 | EE12: 黃國軒 | EF12: A132510465 | EG12: 長男 | EH12: 黃唯禎 | EI12: A232090997 | EJ12: 長女
A13: =ROW()-4 -> 9 | B13: 易居 | D13: 易居A2M10400045 | E13: 續約 | G13: 臺北市士林區天母東路8巷27號2樓之2 | H13: =MID(G13,4,3) -> 士林區 | I13: 三玉段二小段 | J13: 0090-0000 | K13: 21131-000 | L13: 65.32 | M13: 全部 | N13: =O13-365 -> 45197 | O13: 45562 | P13: 30000 | Q13: 16000 | R13: 112-11-30 | S13: 2400 | T13: 112-11-30 | U13: 2400 | V13: 112-12-15 | W13: 2400 | X13: 112-12-29 | Y13: 2400 | Z13: 112-01-15 | AA13: 2400 | AB13: 113-02-29 | AC13: 2400 | AD13: 113-03-29 | AE13: 2400 | AF13: 113-04-30 | AG13: 2400 | AH13: 113-05-15 | AI13: 2400 | AJ13: 113-06-28 | AK13: 2400 | AL13: 113-07-31 | AM13: 2400 | AN13: 113-09-20 | AO13: 2400 | AP13: 113-10-20 | CM13: 邱珮堯 | CN13: U221271947 | CO13: 8220314 | CP13: 314540483912 | CQ13: 新北市土城區延安街42號11樓 | CT13: 3300 | CU13: 112-11-30 | CZ13: 1250 | DA13: 112-11-30 | DB13: 8500 | DC13: 113-09-20 | DH13: =10000-DF13-DD13-DB13-CZ13 -> 250 | EA13: 楊婭鈺 | EB13: C221378035 | EC13: 8080163 | ED13: 0163979765225
A14: =ROW()-4 -> 10 | B14: 易居 | D14: 易居A2M10400046 | E14: 續約 | G14: 臺北市北投區知行路210巷8號 | H14: =MID(G14,4,3) -> 北投區 | I14: 關渡段二小段 | J14: 0475-0000 | K14: 20059-000 | L14: 78.09 | M14: 全部 | N14: =O14-365 -> 45199 | O14: 45564 | P14: 20000 | Q14: 16000 | R14: 112-11-30 | S14: 2400 | T14: 112-11-30 | U14: 2400 | V14: 112-12-15 | W14: 2400 | X14: 112-12-29 | Y14: 2400 | Z14: 112-01-15 | AA14: 2400 | AB14: 113-02-29 | AC14: 2400 | AD14: 113-03-29 | AE14: 2400 | AF14: 113-04-30 | AG14: 2400 | AH14: 113-05-15 | AI14: 2400 | AJ14: 113-06-28 | AK14: 2400 | AL14: 113-07-31 | AM14: 2400 | AN14: 113-09-20 | AO14: 2400 | AP14: 113-10-20 | CM14: 紀林素卿 | CN14: Y200508512 | CO14: 7000021 | CP14: 00023400273791 | CQ14: 臺北市北投區關渡里4鄰大度路三段301巷61號 | CZ14: 10000 | DA14: 113-10-20 | DH14: =10000-DF14-DD14-DB14-CZ14 -> 0 | EA14: 張菀倫 | EB14: A228496525 | EC14: 0122604 | ED14: 360168306764 | EE14: 莊志祥 | EF14: A124376940 | EG14: 配偶 | EH14: 莊雨霏 | EI14: A233002786 | EJ14: 長女 | EK14: 莊晴嵐 | EL14: A233252713 | EM14: 次女
A15: =ROW()-4 -> 11 | B15: 易居 | D15: 易居A2M10400053 | E15: 續約 | G15: 臺北市萬華區艋舺大道55號2樓 | H15: =MID(G15,4,3) -> 萬華區 | I15: 萬華段二小段 | J15: 0648-0000 | K15: 00760-000 | L15: 65.01 | M15: 全部 | N15: =O15-365 -> 45209 | O15: 45574 | P15: 15000 | Q15: 16000 | R15: 112-11-30 | S15: 2400 | T15: 112-11-30 | U15: 2400 | V15: 112-12-15 | W15: 2400 | X15: 112-01-15 | Y15: 2400 | Z15: 113-02-29 | AA15: 2400 | AB15: 113-03-29 | AC15: 2400 | AD15: 113-04-30 | AE15: 2400 | AF15: 113-05-15 | AG15: 2400 | AH15: 113-06-14 | AI15: 2400 | AJ15: 113-07-15 | AK15: 2400 | AL15: 113-09-20 | AM15: 2400 | AN15: 113-10-20 | AO15: 2400 | AP15: 113-11-20 | CM15: 陳進燈 | CN15: A121882227 | CO15: 7000021 | CP15: 24414220511103 | CQ15: 臺北市萬華區艋舺大道55號2樓 | DH15: =10000-DF15-DD15-DB15-CZ15 -> 10000 | EA15: 劉憓陵 | EB15: H221363413 | EC15: 8080417 | ED15: 0417968133556
A16: =ROW()-4 -> 12 | B16: 易居 | D16: 易居A2M10400060 | E16: 續約 | G16: 臺北市內湖區內湖路三段191巷4號5樓 | H16: =MID(G16,4,3) -> 內湖區 | I16: 碧湖段一小段 | J16: 0700-0000 | K16: 00675-000 | L16: 79.7 | M16: 全部 | N16: =O16-365 -> 45223 | O16: 45588 | P16: 17000 | Q16: 16000 | R16: 112-11-30 | S16: 2400 | T16: 112-11-30 | U16: 2400 | V16: 112-12-29 | W16: 2400 | X16: 112-01-15 | Y16: 2400 | Z16: 113-02-29 | AA16: 2400 | AB16: 113-03-29 | AC16: 2400 | AD16: 113-04-30 | AE16: 2400 | AF16: 113-05-15 | AG16: 2400 | AH16: 113-06-28 | AI16: 2400 | AJ16: 113-07-31 | AK16: 2400 | AL16: 113-09-20 | AM16: 2400 | AN16: 113-10-20 | AO16: 2400 | AP16: 113-11-20 | CM16: 連珮淇 | CN16: F226193820 | CO16: 8220266 | CP16: 266540567261 | CQ16: 新北市新莊區福樂街72巷11號2樓 | CZ16: 3990 | DA16: 113-01-15 | DH16: =10000-DF16-DD16-DB16-CZ16 -> 6010 | EA16: 秦忠成 | EB16: A120631566 | EC16: 7000021 | ED16: 00025210200863
A17: =ROW()-4 -> 13 | B17: 易居 | D17: 易居A2M10400064 | E17: 續約 | G17: 臺北市中山區中山北路二段137巷1號2樓之1、2樓之2 | H17: =MID(G17,4,3) -> 中山區 | I17: 中山段一小段 | J17: 0822-0000 | K17: 04572-000 | L17: 37.34 | M17: 全部 | N17: =O17-365 -> 45214 | O17: 45579 | P17: 23000 | Q17: 8000 | R17: 112-11-30 | S17: 2400 | T17: 112-11-30 | U17: 2400 | V17: 112-12-15 | W17: 2400 | X17: 112-01-15 | Y17: 2400 | Z17: 113-02-29 | AA17: 2400 | AB17: 113-03-29 | AC17: 2400 | AD17: 113-04-30 | AE17: 2400 | AF17: 113-05-15 | AG17: 2400 | AH17: 113-06-14 | AI17: 2400 | AJ17: 113-07-15 | AK17: 2400 | AL17: 113-09-20 | AM17: 2400 | AN17: 113-10-20 | AO17: 2400 | AP17: 113-11-20 | CM17: 林岳群 | CN17: A124234296 | CO17: 0051404 | CP17: 140008006233 | CQ17: 臺北市中山區中山北路二段137巷1號2樓之1 | CZ17: 9900 | DA17: 113-10-20 | DH17: =10000-DF17-DD17-DB17-CZ17 -> 100 | EA17: 董乃瑜 | EB17: B221735913 | EC17: 7000021 | ED17: 00216540295118 | EE17: 董南廷 | EF17: B124067321 | EG17: 長子
A18: =ROW()-4 -> 14 | B18: 易居 | D18: 易居A2M10400104 | E18: 續約 | G18: 臺北市士林區重慶北路四段49巷20弄8之1號 | H18: =MID(G18,4,3) -> 士林區 | I18: 福順段三小段 | J18: 0430-0000 | K18: 30181-000 | L18: 47.21 | M18: 全部 | N18: =O18-365 -> 45260 | O18: 45625 | P18: 17000 | Q18: 8000 | R18: 113-01-15 | S18: 2400 | T18: 113-01-15 | U18: 2400 | V18: 113-01-15 | W18: 2400 | X18: 113-02-29 | Y18: 2400 | Z18: 113-03-29 | AA18: 2400 | AB18: 113-04-30 | AC18: 2400 | AD18: 113-05-15 | AE18: 2400 | AF18: 113-06-28 | AG18: 2400 | AH18: 113-07-31 | AI18: 2400 | AJ18: 113-09-20 | AK18: 2400 | AL18: 113-10-20 | AM18: 2400 | AN18: 113-11-20 | AO18: 2400 | AP18: 45646 | CM18: 謝介俊 | CN18: Q122055441 | CO18: 1080014 | CP18: 001010314231 | CQ18: 臺北市士林區重慶北路四段81號6樓之4 | CZ18: 1500 | DA18: 113-11-20 | DH18: =10000-DF18-DD18-DB18-CZ18 -> 8500 | EA18: 楊林寶鳳 | EB18: G201154220 | EC18: 7000021 | ED18: 00014210160833 | EE18: 楊正雄 | EF18: Y100268253 | EG18: 配偶
A19: =ROW()-4 -> 15 | B19: 易居 | D19: 易居A2M10400117 | E19: 續約 | G19: 台北市中正區重慶南路三段15巷5號3樓 | H19: =MID(G19,4,3) -> 中正區 | I19: 南海段三小段 | J19: 0772-0000 | K19: 00225-000 | L19: 93.31 | M19: 全部 | N19: 112/12/31 | O19: 113/12/30 | P19: 29000 | Q19: 16000 | R19: 113-01-31 | S19: 2400 | T19: 113-01-31 | U19: 2400 | V19: 113-02-29 | W19: 2400 | X19: 113-03-29 | Y19: 2400 | Z19: 113-04-30 | AA19: 2400 | AB19: 113-05-15 | AC19: 2400 | AD19: 113-06-28 | AE19: 2400 | AF19: 113-07-31 | AG19: 2400 | AH19: 113-09-20 | AI19: 2400 | AJ19: 113-10-20 | AK19: 2400 | AL19: 113-11-20 | AM19: 2400 | AN19: 45646 | AO19: 2400 | AP19: 114-01-20 | CM19: 陳裕華 | CN19: A200132573 | CO19: 0071727 | CP19: 17250008556 | CQ19: 台北市中正區重慶南路三段15巷5號3樓 | CZ19: 1250 | DA19: 113-02-15 | DB19: 8750 | DC19: 113-03-29 | DH19: =10000-DF19-DD19-DB19-CZ19 -> 0 | EA19: 黃洪菊妹 | EB19: K200057458 | EC19: 7000021 | ED19: 00010680363558 | EE19: 黃德鏜 | EF19: A103136937 | EG19: 配偶
A20: =ROW()-4 -> 16 | B20: 易居 | D20: 易居A2M10400123 | E20: 終止租約 | F20: 114-01-09 | G20: 台北市士林區承德路四段48巷3號3樓 | H20: =MID(G20,4,3) -> 士林區 | I20: 百齡段五小段 | J20: 0560-0000 | K20: 50444-000 | L20: 107.65 | M20: 全部 | N20: 45301 | O20: =N20+365 -> 45666 | P20: 22000 | Q20: 16000 | R20: 113-03-29 | S20: 2400 | T20: 113-03-29 | U20: 2400 | V20: 113-03-29 | W20: 2400 | X20: 113-04-30 | Y20: 2400 | Z20: 113-05-15 | AA20: 2400 | AB20: 113-06-14 | AC20: 2400 | AD20: 113-07-15 | AE20: 2400 | AF20: 113-09-20 | AG20: 2400 | AH20: 113-10-20 | AI20: 2400 | AJ20: 113-11-20 | AK20: 2400 | AL20: 45646 | AM20: 2400 | AN20: 114-01-20 | AO20: 2400 | AP20: 114-02-20 | CM20: 葉克柔 | CN20: F222145640 | CO20: 7000021 | CP20: 0012840972597 | CQ20: 新北市汐止區民族五街16號16樓之2 | CT20: 3300 | CU20: 113-03-29 | CZ20: 9610 | DA20: 113-03-29 | DB20: 390 | DC20: 114-01-20 | DH20: =10000-DF20-DD20-DB20-CZ20 -> 0 | EA20: 曾靖婷 | EB20: K222222226 | EC20: 7000021 | ED20: 00013750605228
A21: =ROW()-4 -> 17 | B21: 易居 | D21: 易居A2M10400145 | E21: 續約 | G21: 台北市北投區開明街15號4樓 | H21: =MID(G21,4,3) -> 北投區 | I21: 開明段一小段 | J21: 0502-0000 | K21: 10767-000 | L21: 107.19 | M21: 全部 | N21: 45323 | O21: =N21+365 -> 45688 | P21: 18000 | Q21: 4000 | R21: 113-04-30 | S21: 2400 | T21: 113-04-30 | U21: 2400 | V21: 113-04-30 | W21: 2400 | X21: 113-05-15 | Y21: 2400 | Z21: 113-06-14 | AA21: 2400 | AB21: 113-07-15 | AC21: 2400 | AD21: 113-09-20 | AE21: 2400 | AF21: 113-10-20 | AG21: 2400 | AH21: 113-11-20 | AI21: 2400 | AJ21: 45646 | AK21: 2400 | AL21: 114-01-20 | AM21: 2400 | AN21: 114-02-20 | AO21: 2400 | AP21: 114-03-20 | CM21: 蔡梅鶯 | CN21: Q202183893 | CO21: 8160027 | CP21: 00222003270700 | CQ21: 台北市大安區通化街111號6樓 | DH21: =10000-DF21-DD21-DB21-CZ21 -> 10000 | EA21: 吳小芳 | EB21: C220168124 | EC21: 7000021 | ED21: 00024580048810 | EE21: 余浩東 | EF21: F125954194 | EG21: 兒子 | EH21: 余培亞 | EI21: F126565280 | EJ21: 兒子
A22: =ROW()-4 -> 18 | B22: 易居 | D22: 易居A2M10400146 | E22: 中止租約 | F22: 113-11-05 | G22: 台北市中山區農安街227巷9弄4號4樓 | H22: =MID(G22,4,3) -> 中山區 | I22: 榮興段七小段 | J22: 0015-0001 | K22: 00216-000 | L22: 89.99 | M22: 全部 | N22: 45323 | O22: =N22+365 -> 45688 | P22: 32000 | Q22: 16000 | R22: 113-04-30 | S22: 2400 | T22: 113-04-30 | U22: 2400 | V22: 113-04-30 | W22: 2400 | X22: 113-05-15 | Y22: 2400 | Z22: 113-06-14 | AA22: 2400 | AB22: 113-07-15 | AC22: 2400 | AD22: 113-09-20 | AE22: 2400 | AF22: 113-10-20 | AG22: 2400 | AH22: 113-11-20 | AI22: 2400 | AJ22: 45646 | AK22: 2400 | AL22: 114-01-20 | AM22: - | AN22: - | AO22: - | AP22: - | CM22: 陳願宗 | CN22: A125703950 | CO22: 8222123 | CP22: 123540031568 | CQ22: 新北市板橋區環河西路四段2235號10樓 | CR22: 陳明宗 | CS22: A125765003 | DH22: =10000-DF22-DD22-DB22-CZ22 -> 10000 | DI22: 10000 | DJ22: 10000 | DK22: 10000 | DL22: 10000 | DM22: 10000 | DN22: 10000 | DO22: 10000 | DP22: 10000 | DQ22: 10000 | DR22: 10000 | DS22: 10000 | DT22: 10000 | DU22: 10000 | DV22: 10000 | DW22: 10000 | DX22: 10000 | DY22: 10000 | DZ22: 10000 | EA22: 彭秋桂 | EB22: A221331281 | EC22: 8222145 | ED22: 145540067934
A23: =ROW()-4 -> 19 | B23: 易居 | D23: 易居A2M10400147 | E23: 續約 | G23: 台北市大同區歸綏街209號4樓之5 | H23: =MID(G23,4,3) -> 大同區 | I23: 延平段一小段 | J23: 0484-0000 | K23: 02473-000 | L23: 66.46 | M23: 全部 | N23: 45337 | O23: =N23+365 -> 45702 | P23: 20000 | Q23: 4000 | R23: 113-04-30 | S23: 2400 | T23: 113-04-30 | U23: 2400 | V23: 113-04-30 | W23: 2400 | X23: 113-05-15 | Y23: 2400 | Z23: 113-06-14 | AA23: 2400 | AB23: 113-07-15 | AC23: 2400 | AD23: 113-09-20 | AE23: 2400 | AF23: 113-10-20 | AG23: 2400 | AH23: 113-11-20 | AI23: 2400 | AJ23: 45646 | AK23: 2400 | AL23: 114-01-20 | AM23: 2400 | AN23: 114-02-20 | AO23: 2400 | AP23: 114-03-20 | CM23: 李淑霞 | CN23: A222613639 | CO23: 0130187 | CP23: 018505205789 | CQ23: 新北市三重區永福街179巷24號2樓 | CZ23: 10000 | DA23: 45736 | DH23: =10000-DF23-DD23-DB23-CZ23 -> 0 | EA23: 蕭碧霞 | EB23: U200322823 | EC23: 7000021 | ED23: 00913110178543
A24: =ROW()-4 -> 20 | B24: 易居 | D24: 易居A2M10400149 | E24: 中止租約 | F24: 113-05-31 | G24: 臺北市大同區民族西路303巷5弄5號2樓 | H24: =MID(G24,4,3) -> 大同區 | I24: 文昌段二小段 | J24: 0591-0000,0592-0000,0593-0000 | K24: 01300-000 | L24: 73.7 | M24: 全部 | N24: 45337 | O24: =N24+365 -> 45702 | P24: 21000 | Q24: 16000 | R24: 113-05-31 | S24: 2400 | T24: 113-05-31 | U24: 2400 | V24: 113-05-31 | W24: 2400 | X24: 113-05-31 | Y24: 2400 | Z24: 113-06-14 | AA24: - | AB24: - | AC24: - | AD24: - | AE24: - | AF24: - | AG24: - | AH24: - | AI24: - | AJ24: - | AK24: - | AL24: - | AM24: - | AN24: - | AO24: - | AP24: - | CM24: 陳泓誠 | CN24: F123352638 | CO24: 0060109 | CP24: 0100765789642 | CQ24: 新北市三重區自強路二段78號 | CT24: 3300 | CU24: 113-05-31 | CZ24: 10000 | DA24: 113-06-14 | DH24: =10000-DF24-DD24-DB24-CZ24 -> 0 | EA24: 李睿凌 | EB24: A226336633 | EC24: 0130659 | ED24: 065506103953 | EE24: 林建傑 | EF24: A126014023 | EG24: 丈夫 | EH24: 黃淑慈 | EI24: F220491345 | EJ24: 母親 | EK24: 林芊愷 | EL24: A233056088 | EM24: 女兒
A25: =ROW()-4 -> 21 | B25: 易居 | D25: 易居A2M10400166 | E25: 續約 | G25: 臺北市文山區興隆路四段88號4樓 | H25: =MID(G25,4,3) -> 文山區 | I25: 實踐段二小段 | J25: 0017-0000,0018-0000 | K25: 00430-000 | L25: 76.71 | M25: 全部 | N25: 45376 | O25: =N25+364 -> 45740 | P25: 24000 | Q25: 16000 | R25: 113-05-15 | S25: 2400 | T25: 113-05-15 | U25: 2400 | V25: 113-05-15 | W25: 2400 | X25: 113-06-28 | Y25: 2400 | Z25: 113-07-31 | AA25: 2400 | AB25: 113-09-20 | AC25: 2400 | AD25: 113-10-20 | AE25: 2400 | AF25: 113-11-20 | AG25: 2400 | AH25: 45646 | AI25: 2400 | AJ25: 114-01-20 | AK25: 2400 | AL25: 114-02-20 | AM25: 2400 | AN25: 114-03-20 | AO25: 2400 | AP25: 114-04-20 | CM25: 李昆山 | CN25: K120321091 | CO25: 7000021 | CP25: 00027039003352 | CQ25: 新北市新店區三民路117巷8弄8號1樓 | CT25: 3300 | CU25: 113-05-15 | CZ25: 1250 | DA25: 113-05-15 | DH25: =10000-DF25-DD25-DB25-CZ25 -> 8750 | EA25: 李玉如 | EB25: A222772713 | EC25: 0060936 | ED25: 0936872076226
A26: =ROW()-4 -> 22 | B26: 易居 | D26: 易居A2M10400171 | E26: 續約 | G26: 臺北市士林區重慶北路四段49巷20弄8之1號2樓 | H26: =MID(G26,4,3) -> 士林區 | I26: 福順段三小段 | J26: 0430-0000 | K26: 30740-000 | L26: 52.89 | M26: 全部 | N26: 45366 | O26: =N26+364 -> 45730 | P26: 17000 | Q26: 4000 | R26: 113-05-15 | S26: 2400 | T26: 113-05-15 | U26: 2400 | V26: 113-05-15 | W26: 2400 | X26: 113-06-14 | Y26: 2400 | Z26: 113-07-15 | AA26: 2400 | AB26: 113-09-20 | AC26: 2400 | AD26: 113-10-20 | AE26: 2400 | AF26: 113-11-20 | AG26: 2400 | AH26: 45646 | AI26: 2400 | AJ26: 114-01-20 | AK26: 2400 | AL26: 114-02-20 | AM26: 2400 | AN26: 114-03-20 | AO26: 2400 | AP26: 114-04-20 | CM26: 謝介俊 | CN26: Q122055441 | CO26: 1080014 | CP26: 001010314231 | CQ26: 臺北市士林區重慶北路四段81號6樓之4 | CZ26: 1500 | DA26: 113-12-20 | DB26: 3000 | DC26: 114-03-20 | DD26: 2000 | DE26: 45767 | DH26: =10000-DF26-DD26-DB26-CZ26 -> 3500 | EA26: 陳姵邑 | EB26: A222240323 | EC26: 7000021 | ED26: 00011140527957
A27: =ROW()-4 -> 23 | B27: 易居 | D27: 易居A2M10400176 | E27: 續約 | G27: 臺北市大同區長安西路287號11樓之15 | H27: =MID(G27,4,3) -> 大同區 | I27: 玉泉段二小段 | J27: 0389-0000 | K27: 02911-000 | L27: 53.28 | M27: 全部 | N27: 45376 | O27: =N27+364 -> 45740 | P27: 25000 | Q27: 16000 | R27: 113-05-15 | S27: 2400 | T27: 113-05-15 | U27: 2400 | V27: 113-05-15 | W27: 2400 | X27: 113-06-28 | Y27: 2400 | Z27: 113-07-31 | AA27: 2400 | AB27: 113-09-20 | AC27: 2400 | AD27: 113-10-20 | AE27: 2400 | AF27: 113-11-20 | AG27: 2400 | AH27: 45646 | AI27: 2400 | AJ27: 114-01-20 | AK27: 2400 | AL27: 114-02-20 | AM27: 2400 | AN27: 114-03-20 | AO27: 2400 | AP27: 114-04-20 | CM27: 王裕貿 | CN27: A125721485 | CO27: 0130420 | CP27: 042508157449 | CQ27: 臺中市西區樂群街270號九樓之1 | CT27: 3300 | CU27: 113-05-15 | CZ27: 10000 | DA27: 45736 | DH27: =10000-DF27-DD27-DB27-CZ27 -> 0 | EA27: 林渝庭 | EB27: E224570024 | EC27: 8220303 | ED27: 303540376522
A28: =ROW()-4 -> 24 | B28: 易居 | D28: 易居A2M10400182 | E28: 續約 | G28: 臺北市北投區永興路二段33巷12弄19號2樓 | H28: =MID(G28,4,3) -> 北投區 | I28: 開明段一小段 | J28: 0738-0000 | K28: 10752-000 | L28: 85.76 | M28: 全部 | N28: 45383 | O28: =N28+364 -> 45747 | P28: 15000 | Q28: 16000 | R28: 113-05-31 | S28: 2400 | T28: 113-05-31 | U28: 2400 | V28: 113-06-14 | W28: 2400 | X28: 113-07-15 | Y28: 2400 | Z28: 113-09-20 | AA28: 2400 | AB28: 113-10-20 | AC28: 2400 | AD28: 113-11-20 | AE28: 2400 | AF28: 45646 | AG28: 2400 | AH28: 114-01-20 | AI28: 2400 | AJ28: 114-02-20 | AK28: 2400 | AL28: 114-03-20 | AM28: 2400 | AN28: 114-04-20 | AO28: =AM28 -> 2400 | AP28: 45797 | CM28: 游慈忠 | CN28: G121468956 | CO28: 0127406 | CP28: 00740168914818 | CQ28: 臺北市北投區永興路二段33巷12弄19號2樓 | CZ28: 800 | DA28: 113-05-31 | DB28: 9200 | DC28: 113-11-20 | DH28: =10000-DF28-DD28-DB28-CZ28 -> 0 | EA28: 吳美緻 | EB28: P220822230 | EC28: 8120861 | ED28: 20861000152206
A29: =ROW()-4 -> 25 | B29: 易居 | D29: 易居A2M10400186 | E29: 續約 | G29: 臺北市萬華區長泰街290號2樓 | H29: =MID(G29,4,3) -> 萬華區 | I29: 華中段二小段 | J29: 0856-0000 | K29: 01847-000 | L29: 75.73 | M29: 全部 | N29: 45397 | O29: =N29+364 -> 45761 | P29: 22000 | Q29: 4000 | R29: 113-05-31 | S29: 2400 | T29: 113-05-31 | U29: 2400 | V29: 113-06-14 | W29: 2400 | X29: 113-07-15 | Y29: 2400 | Z29: 113-09-20 | AA29: 2400 | AB29: 113-10-20 | AC29: 2400 | AD29: 113-11-20 | AE29: 2400 | AF29: 45646 | AG29: 2400 | AH29: 114-01-20 | AI29: 2400 | AJ29: 114-02-20 | AK29: 2400 | AL29: 114-03-20 | AM29: 2400 | AN29: 114-04-20 | AO29: =AM29 -> 2400 | AP29: 45797 | CM29: 謝昕倫 | CN29: F221904458 | CO29: 0065355 | CP29: 5355765311421 | CQ29: 新北市中和區景新街328號10樓之1 | CZ29: 7500 | DA29: 113-06-14 | DH29: =10000-DF29-DD29-DB29-CZ29 -> 2500 | EA29: 黃亮文 | EB29: A103623319 | EC29: 7000021 | ED29: 00013131283321 | EE29: 洪秀蘭 | EF29: F202337697 | EG29: 配偶 | EH29: 黃仕杰 | EI29: A127294847 | EJ29: 兒子
A30: =ROW()-4 -> 26 | B30: 易居 | D30: 易居A2M10400187 | E30: 續約 | G30: 臺北市內湖區康樂街61巷79弄2號2樓 | H30: =MID(G30,4,3) -> 內湖區 | I30: 東湖段一小段 | J30: 0002-0000 | K30: 01451-000 | L30: 80.47 | M30: 全部 | N30: 45397 | O30: =N30+364 -> 45761 | P30: 33000 | Q30: 16000 | R30: 113-05-31 | S30: 2400 | T30: 113-05-31 | U30: 2400 | V30: 113-06-14 | W30: 2400 | X30: 113-07-15 | Y30: 2400 | Z30: 113-09-20 | AA30: 2400 | AB30: 113-10-20 | AC30: 2400 | AD30: 113-11-20 | AE30: 2400 | AF30: 45646 | AG30: 2400 | AH30: 114-01-20 | AI30: 2400 | AJ30: 114-02-20 | AK30: 2400 | AL30: 114-03-20 | AM30: 2400 | AN30: 114-04-20 | AO30: =AM30 -> 2400 | AP30: 45797 | CM30: 劉文啓 | CN30: K121332150 | CO30: 0172370 | CP30: 23710601117 | CQ30: 臺北市中正區臨沂街75巷2之3號2樓之1 | CT30: 3300 | CU30: 113-05-31 | CZ30: 10000 | DA30: 114-02-20 | DH30: =10000-DF30-DD30-DB30-CZ30 -> 0 | EA30: 李香君 | EB30: A226122675 | EC30: 7000021 | ED30: 00026740169968 | EE30: 張棕傑 | EF30: K121909928 | EG30: 配偶 | EH30: 李閔浩 | EI30: F135495657 | EJ30: 兒子 | EK30: 李茹閑 | EL30: F234870550 | EM30: 女兒
A31: =ROW()-4 -> 27 | B31: 易居 | D31: 易居A2M10400206 | E31: 續約 | G31: 臺北市士林區葫蘆街29巷36號 | H31: =MID(G31,4,3) -> 士林區 | I31: 海光段三小段 | J31: 0409-0000 | K31: 31026-000 | L31: 81.65 | M31: 全部 | N31: 45413 | O31: =N31+364 -> 45777 | P31: 20000 | Q31: 16000 | R31: 113-06-14 | S31: 2400 | T31: 113-06-14 | U31: 2400 | V31: 113-07-15 | W31: 2400 | X31: 113-09-20 | Y31: 2400 | Z31: 113-10-20 | AA31: 2400 | AB31: 113-11-20 | AC31: 2400 | AD31: 45646 | AE31: 2400 | AF31: 114-01-20 | AG31: 2400 | AH31: 114-02-20 | AI31: 2400 | AJ31: 114-03-20 | AK31: 2400 | AL31: 114-04-20 | AM31: =AK31 -> 2400 | AN31: 45797 | AO31: =AM31 -> 2400 | AP31: 45828 | CM31: 陳福海 | CN31: Y100160341 | CO31: 1080041 | CP31: 008010082030 | CQ31: 臺北市士林區延平北路5段245巷2號2樓 | CZ31: 10000 | DA31: 113-11-20 | DH31: =10000-DF31-DD31-DB31-CZ31 -> 0 | EA31: 郭連福 | EB31: A103677737 | EC31: 7000021 | ED31: 00014210961732 | EE31: 張麗春 | EF31: F201400708 | EG31: 妻子
A32: =ROW()-4 -> 28 | B32: 易居 | D32: 易居A2M10400220 | E32: 中止租約 | F32: 45713 | G32: 臺北市士林區文林路587巷9弄9號 | H32: =MID(G32,4,3) -> 士林區 | I32: 陽明段三小段 | J32: 0165-0000 | K32: 30569-000 | L32: 230.67 | M32: 全部 | N32: 45422 | O32: =N32+364 -> 45786 | P32: 19500 | Q32: 8000 | R32: 113-07-15 | S32: 2400 | T32: 113-07-15 | U32: 2400 | V32: 113-07-15 | W32: 2400 | X32: 113-09-20 | Y32: 2400 | Z32: 113-10-20 | AA32: 2400 | AB32: 113-11-20 | AC32: 2400 | AD32: 45646 | AE32: 2400 | AF32: 114-01-20 | AG32: 2400 | AH32: 114-02-20 | AI32: 2400 | AJ32: 114-03-20 | AK32: 2400 | AL32: 114-04-20 | AM32: - | AN32: - | AO32: - | AP32: - | CM32: 呂寶玉 | CN32: Q221286275 | CO32: 0050108 | CP32: 010005451677 | CQ32: 臺北市士林區文林路587巷9弄9號3樓 | CR32: 蔡志鏗 | CS32: N121448931 | CZ32: 10000 | DA32: 113-09-20 | DH32: =10000-DF32-DD32-DB32-CZ32 -> 0 | EA32: 賴秀明 | EB32: L120208388 | EC32: 7000021 | ED32: 00017730601092
A33: =ROW()-4 -> 29 | B33: 易居 | D33: 易居A2M10400221 | E33: 自然中止 | F33: 45791 | G33: 臺北市信義區中坡南路22巷12號4樓 | H33: =MID(G33,4,3) -> 信義區 | I33: 福德段一小段 | J33: 0038-0000 | K33: 02811-000 | L33: 123.82 | M33: 全部 | N33: 45426 | O33: =N33+364 -> 45790 | P33: 26500 | Q33: 16000 | R33: 113-07-15 | S33: 2400 | T33: 113-07-15 | U33: 2400 | V33: 113-07-15 | W33: 2400 | X33: 113-09-20 | Y33: 2400 | Z33: 113-10-20 | AA33: 2400 | AB33: 113-11-20 | AC33: 2400 | AD33: 45646 | AE33: 2400 | AF33: 114-01-20 | AG33: 2400 | AH33: 114-02-20 | AI33: 2400 | AJ33: 114-03-20 | AK33: 2400 | AL33: 114-04-20 | AM33: =AK33 -> 2400 | AN33: 45797 | AO33: =AM33 -> 2400 | AP33: 45828 | CM33: 李逸峰 | CN33: P121264187 | CO33: 0065355 | CP33: 5355765339716 | CQ33: 新北市新店區寶橋路78巷9號17樓 | CZ33: 850 | DA33: 113-07-15 | DB33: 9150 | DC33: 113-11-20 | DH33: =10000-DF33-DD33-DB33-CZ33 -> 0 | EA33: 魏浩倫 | EB33: H123810879 | EC33: 0072816 | ED33: 28168208676
A34: =ROW()-4 -> 30 | B34: 易居 | D34: 易居A2M10400222 | E34: 中止租約 | F34: 113-10-23 | G34: 臺北市內湖區行善路25巷1弄2號5樓 | H34: =MID(G34,4,3) -> 內湖區 | I34: 舊宗段 | J34: 0113-0000 | K34: 00958-000 | L34: 124.08 | M34: 全部 | N34: 45432 | O34: =N34+364 -> 45796 | P34: 29000 | Q34: 16000 | R34: 113-07-15 | S34: 2400 | T34: 113-07-15 | U34: 2400 | V34: 113-07-31 | W34: 2400 | X34: 113-09-20 | Y34: 2400 | Z34: 113-10-20 | AA34: 2400 | AB34: 113-11-20 | AC34: 2400 | AD34: 45646 | AE34: - | AF34: - | AG34: - | AH34: - | AI34: - | AJ34: - | AK34: - | AL34: - | AM34: - | AN34: - | AO34: - | AP34: - | CM34: 駱文卿 | CN34: A121289842 | CO34: 8061353 | CP34: 00168105745010 | CQ34: 臺北市松山區延壽街432號5樓 | CZ34: 3150 | DA34: 113-10-20 | DB34: 1050 | DC34: 113-12-20 | DH34: =10000-DF34-DD34-DB34-CZ34 -> 5800 | EA34: 朱榮康 | EB34: E101471875 | EC34: 0061298 | ED34: 0331765252551 | EE34: 蔡麗香 | EF34: A222250623 | EG34: 配偶
A35: =ROW()-4 -> 31 | B35: 易居 | D35: 易居A2M10400223 | E35: 自然中止 | F35: 45791 | G35: 臺北市萬華區成都路108號8樓之2 | H35: =MID(G35,4,3) -> 萬華區 | I35: 直興段一小段 | J35: 0131-0000 | K35: 01588-000 | L35: 53.35 | M35: 全部 | N35: 45426 | O35: =N35+364 -> 45790 | P35: 21800 | Q35: 16000 | R35: 113-07-15 | S35: 2400 | T35: 113-07-15 | U35: 2400 | V35: 113-07-15 | W35: 2400 | X35: 113-09-20 | Y35: 2400 | Z35: 113-10-20 | AA35: 2400 | AB35: 113-11-20 | AC35: 2400 | AD35: 45646 | AE35: 2400 | AF35: 114-01-20 | AG35: 2400 | AH35: 114-02-20 | AI35: 2400 | AJ35: 114-03-20 | AK35: 2400 | AL35: 114-04-20 | AM35: =AK35 -> 2400 | AN35: 45797 | AO35: =AM35 -> 2400 | AP35: 45828 | CM35: 徐悅哲 | CN35: A126950695 | CO35: 8120919 | CP35: 20911000088628 | CQ35: 臺北市萬華區德昌街262號7樓 | CT35: 3300 | CU35: 113-07-15 | CZ35: 850 | DA35: 113-07-15 | DB35: 2734 | DC35: 113-07-31 | DD35: 6416 | DE35: 45797 | DH35: =10000-DF35-DD35-DB35-CZ35 -> 0 | EA35: 許雀蘭 | EB35: N220571586 | EC35: 7000021 | ED35: 00810110520945 | EE35: 葉錫昇 | EF35: N120601087 | EG35: 配偶
A36: =ROW()-4 -> 32 | B36: 易居 | D36: 易居A2M10400251 | E36: 續約 | G36: 台北市大同區重慶北路三段243巷29號4樓 | H36: =MID(G36,4,3) -> 大同區 | I36: 大龍段三小段 | J36: 0518-0000 | K36: 01823-000 | L36: 59.72 | M36: 全部 | N36: 45458 | O36: =N36+364 -> 45822 | P36: 22000 | Q36: 16000 | R36: 113-07-31 | S36: 2400 | T36: 113-07-31 | U36: 2400 | V36: 113-09-20 | W36: 2400 | X36: 113-10-20 | Y36: 2400 | Z36: 113-11-20 | AA36: 2400 | AB36: 45646 | AC36: 2400 | AD36: 114-01-20 | AE36: 2400 | AF36: 114-02-20 | AG36: 2400 | AH36: 114-03-20 | AI36: 2400 | AJ36: 114-04-20 | AK36: =AI36 -> 2400 | AL36: 45797 | AM36: =AK36 -> 2400 | AN36: 45828 | AO36: =AM36 -> 2400 | AP36: 45858 | CM36: 趙秀英 | CN36: F290198420 | CO36: 8030010 | CP36: 001501016758 | CQ36: 臺北市大同區重慶北路三段243巷29號4樓 | CZ36: 850 | DA36: 113-09-20 | DB36: 9150 | DC36: 113-11-20 | DH36: =10000-DF36-DD36-DB36-CZ36 -> 0 | EA36: 高博崇 | EB36: A131051967 | EC36: 0060969 | ED36: 0969765935840 | EE36: 黃蓉郁 | EF36: G220094829 | EG36: 母親
A37: =ROW()-4 -> 33 | B37: 易居 | D37: 易居A2M10400255 | E37: 續約 | G37: 臺北市北投區中山路47號5樓之12 | H37: =MID(G37,4,3) -> 北投區 | I37: 新民段一小段 | J37: 0387-0000 | K37: 10993-000 | L37: 32.44 | M37: 全部 | N37: 45453 | O37: =N37+364 -> 45817 | P37: 10500 | Q37: 16000 | R37: 113-09-20 | S37: 2400 | T37: 113-09-20 | U37: 2400 | V37: 113-09-20 | W37: 2400 | X37: 113-10-20 | Y37: 2400 | Z37: 113-11-20 | AA37: 2400 | AB37: 45646 | AC37: 2400 | AD37: 114-01-20 | AE37: 2400 | AF37: 114-02-20 | AG37: 2400 | AH37: 114-03-20 | AI37: 2400 | AJ37: 114-04-20 | AK37: =AI37 -> 2400 | AL37: 45797 | AM37: =AK37 -> 2400 | AN37: 45828 | AO37: =AM37 -> 2400 | AP37: 45858 | CM37: 張芳生 | CN37: B120871356 | CO37: 1030949 | CP37: 0949500103895 | CQ37: 臺北市北投區中山路47號5樓之12 | CZ37: 1300 | DA37: 113-09-20 | DH37: =10000-DF37-DD37-DB37-CZ37 -> 8700 | EA37: 葉少強 | EB37: S123441005 | EC37: 0123604 | ED37: 81680002022911 | EE37: 葉秋煌 | EF37: R103097206 | EG37: 父親 | EH37: 鄭蓉 | EI37: R290011383 | EJ37: 母親
A38: =ROW()-4 -> 34 | B38: 易居 | D38: 易居A2M10400266 | E38: 續約 | G38: 臺北市北投區稻香路229號4樓 | H38: =MID(G38,4,3) -> 北投區 | I38: 桃源段二小段 | J38: 0069-0000 | K38: 21548-000 | L38: 83.28 | M38: 全部 | N38: 45467 | O38: =N38+364 -> 45831 | P38: 31000 | Q38: 16000 | R38: 113-09-20 | S38: 2400 | T38: 113-09-20 | U38: 2400 | V38: 113-09-20 | W38: 2400 | X38: 113-10-20 | Y38: 2400 | Z38: 113-11-20 | AA38: 2400 | AB38: 45646 | AC38: 2400 | AD38: 114-01-20 | AE38: 2400 | AF38: 114-02-20 | AG38: 2400 | AH38: 114-03-20 | AI38: 2400 | AJ38: 114-04-20 | AK38: =AI38 -> 2400 | AL38: 45797 | AM38: =AK38 -> 2400 | AN38: 45828 | AO38: =AM38 -> 2400 | AP38: 45858 | CM38: 葉庭吟 | CN38: S224287258 | CO38: 8081056 | CP38: 1056979057693 | CQ38: 臺北市松山區八德路四段758號4樓 | CT38: 4500 | CU38: 113-09-20 | CZ38: 10000 | DA38: 45828 | DH38: =10000-DF38-DD38-DB38-CZ38 -> 0 | EA38: 施仟龍 | EB38: N123108476 | EC38: 8220185 | ED38: 185540132324 | EE38: 伍珮婕 | EF38: T223109443 | EG38: 配偶 | EH38: 施向擎 | EI38: A133140556 | EJ38: 兒子 | EK38: 施采媛 | EL38: A233169955 | EM38: 女兒
A39: =ROW()-4 -> 35 | B39: 易居 | D39: 易居A2M10400276 | E39: 中止租約 | F39: 113-12-15 | G39: 臺北市南港區中南街50號3樓 | H39: =MID(G39,4,3) -> 南港區 | I39: 南港段二小段 | J39: 0769-0001，0770-0000 | K39: 01113-000 | L39: 111.75 | M39: 全部 | N39: 45489 | O39: =N39+364 -> 45853 | P39: 33000 | Q39: 4000 | R39: 113-09-20 | S39: 2400 | T39: 113-09-20 | U39: 2400 | V39: 113-10-20 | W39: 2400 | X39: 113-11-20 | Y39: 2400 | Z39: 45646 | AA39: 2400 | AB39: 114-01-20 | AC39: 2400 | AD39: 114-02-20 | AE39: - | AF39: - | AG39: - | AH39: - | AI39: - | AJ39: - | AK39: - | AL39: - | AM39: - | AN39: - | AO39: - | AP39: - | CM39: 廖德璋 | CN39: F120557935 | CO39: 1180774 | CP39: 07745000091485 | CQ39: 新北市汐止區國興街22巷4號 | CZ39: 700 | DA39: 113-12-20 | DH39: =10000-DF39-DD39-DB39-CZ39 -> 9300 | EA39: 林柏宇 | EB39: R124821195 | EC39: 0131036 | ED39: 699513804664 | EE39: 林忠興 | EF39: R122203475 | EG39: 父親 | EH39: 蔣雪娟 | EI39: R222084230 | EJ39: 母親 | EK39: 林陳鳳英 | EL39: R202688581 | EM39: 祖母
A40: =ROW()-4 -> 36 | B40: 易居 | D40: 易居A2M10400293 | E40: 自然中止 | F40: 45869 | G40: 臺北市士林區至善路三段101號 | H40: =MID(G40,4,3) -> 士林區 | I40: 至善段一小段 | J40: 0330-0000 | K40: 10059-000 | L40: 67.05 | M40: 全部 | N40: 45505 | O40: =N40+364 -> 45869 | P40: 13000 | Q40: 16000 | R40: 113-10-20 | S40: 2400 | T40: 113-10-20 | U40: 2400 | V40: 113-11-20 | W40: 2400 | X40: 45646 | Y40: 2400 | Z40: 114-01-20 | AA40: 2400 | AB40: 114-02-20 | AC40: 2400 | AD40: 114-03-20 | AE40: 2400 | AF40: 114-04-20 | AG40: =AE40 -> 2400 | AH40: 45797 | AI40: =AG40 -> 2400 | AJ40: 45828 | AK40: =AI40 -> 2400 | AL40: 45858 | AM40: =AK40 -> 2400 | AN40: 45889 | AO40: 2400 | AP40: 45920 | CM40: 李進興 | CN40: Y120298177 | CO40: 7000021 | CP40: 00012841016102 | CQ40: 臺北市士林區至善路三段275號 | CZ40: 1250 | DA40: 113-10-20 | DH40: =10000-DF40-DD40-DB40-CZ40 -> 8750 | EA40: 楊志祥 | EB40: W100280072 | EC40: 0041539 | ED40: 153004710413
...

Sheet 包租 
A1: 序號 | B1: 業者 | C1: 轉期/換居 | D1: 代租代管 | G1: 租賃契約資料 | S1: 業者 | CU1: 房東 | EI1: 房客
D2: 媒合編號 | E2: 異動原因 (例：自然終止、中止租約) | F2: 自然/中止租約日期(xxx-xx-xx) | G2: 房屋座落地址 | H2: 行政區 | I2: 地段 | J2: 地號(xxxx-xxxx/xxxx-xxxx) | K2: 建號(xxxxx-xxxx) | L2: 謄本面積 (m²) | M2: 租賃範圍 (全部/部分) | N2: 轉租 約起日(xxx/xx/xx) | O2: 轉租 約訖日(xxx/xx/xx) | P2: 包租 約起日(xxx/xx/xx) | Q2: 包租 約訖日(xxx/xx/xx) | R2: 簽約租金 | S2: 開發費 | U2: 公證費(1) | W2: 公證費(2) | Y2: 公證費(3) | AA2: 第一年包管費 | AY2: 第二年包管費 | BW2: 第三年包管費 | CU2: 房東姓名(代表人) | CV2: 基本資料 | CZ2: 房東姓名(共有人/共有人) | DA2: 身分證(共有人/共有人) | DB2: 修繕費 | DJ2: 修繕費餘額 | DK2: 第一年保險 | DM2: 修繕費 | DU2: 修繕費餘額 | DV2: 第二年保險 | DX2: 修繕費 | EF2: 修繕費餘額 | EG2: 第三年保險 | EI2: 代表人匯款資料 | EM2: 代表人家庭成員 | EV2: 共住人/共住人匯款資料 | FA2: 共住人家庭成員 | FD2: 公證費(1) | FF2: 公證費(2) | FH2: 公證費(3) | FJ2: 第一年租金補貼 | GH2: 第二年租金補貼 | HF2: 第三年租金補貼
S3: 開發費 | T3: 撥款日期(xxx-xx-xx) | U3: 公證費 | V3: 撥款日期(xxx-xx-xx) | W3: 公證費 | X3: 撥款日期 | Y3: 公證費 | Z3: 撥款日期 | AA3: 第一期 | AC3: 第二期 | AE3: 第三期 | AG3: 第四期 | AI3: 第五期 | AK3: 第六期 | AM3: 第七期 | AO3: 第八期 | AQ3: 第九期 | AS3: 第十期 | AU3: 第十一期 | AW3: 第十二期 | AY3: 第十三期 | BA3: 第十四期 | BC3: 第十五期 | BE3: 第十六期 | BG3: 第十七期 | BI3: 第十八期 | BK3: 第十九期 | BM3: 第二十期 | BO3: 第二十一期 | BQ3: 第二十二期 | BS3: 第二十三期 | BU3: 第二十四期 | BW3: 第二十五期 | BY3: 第二十六期 | CA3: 第二十七期 | CC3: 第二十八期 | CE3: 第二十九期 | CG3: 第三十期 | CI3: 第三十一期 | CK3: 第三十二期 | CM3: 第三十三期 | CO3: 第三十四期 | CQ3: 第三十五期 | CS3: 第三十六期 | CV3: 身分證(代表人) | CW3: 銀行代碼 (7碼) | CX3: 帳號 | CY3: 通訊地址 | DB3: 第一年(1) | DD3: 第一年(2) | DF3: 第一年(3) | DH3: 第一年(4) | DK3: 保險金額 | DL3: 撥款日期(xxx-xx-xx) | DM3: 第二年(1) | DO3: 第二年(2) | DQ3: 第二年(3) | DS3: 第二年(4) | DV3: 保險金額 | DW3: 撥款日期 | DX3: 第三年(1) | DZ3: 第三年(2) | EB3: 第三年(3) | ED3: 第三年(4) | EG3: 保險金額 | EH3: 撥款日期 | EI3: 房客姓名 | EJ3: 身分證 | EK3: 銀行代碼 (7碼) | EL3: 帳號 | EM3: 親屬姓名(1) | EP3: 親屬姓名(2) | ES3: 親屬姓名(3) | EV3: 房客姓名 | EW3: 身分別 | EX3: 身分證 | EY3: 銀行代碼 (7碼) | EZ3: 帳號 | FA3: 親屬姓名 | FD3: 公證費 | FE3: 撥款日期(xxx-xx-xx) | FF3: 公證費 | FG3: 撥款日期 | FH3: 公證費 | FI3: 撥款日期 | FJ3: 第一期 | FL3: 第二期 | FN3: 第三期 | FP3: 第四期 | FR3: 第五期 | FT3: 第六期 | FV3: 第七期 | FX3: 第八期 | FZ3: 第九期 | GB3: 第十期 | GD3: 第十一期 | GF3: 第十二期 | GH3: 第十三期 | GJ3: 第十四期 | GL3: 第十五期 | GN3: 第十六期 | GP3: 第十七期 | GR3: 第十八期 | GT3: 第十九期 | GV3: 第二十期 | GX3: 第二十一期 | GZ3: 第二十二期 | HB3: 第二十三期 | HD3: 第二十四期 | HF3: 第二十五期 | HH3: 第二十六期 | HJ3: 第二十七期 | HL3: 第二十八期 | HN3: 第二十九期 | HP3: 第三十期 | HR3: 第三十一期 | HT3: 第三十二期 | HV3: 第三十三期 | HX3: 第三十四期 | HZ3: 第三十五期 | IB3: 第三十六期
AA4: 包管費 | AB4: 撥款日期(xxx-xx-xx) | AC4: 包管費 | AD4: 撥款日期(xxx-xx-xx) | AE4: 包管費 | AF4: 撥款日期(xxx-xx-xx) | AG4: 包管費 | AH4: 撥款日期(xxx-xx-xx) | AI4: 包管費 | AJ4: 撥款日期(xxx-xx-xx) | AK4: 包管費 | AL4: 撥款日期(xxx-xx-xx) | AM4: 包管費 | AN4: 撥款日期(xxx-xx-xx) | AO4: 包管費 | AP4: 撥款日期(xxx-xx-xx) | AQ4: 包管費 | AR4: 撥款日期(xxx-xx-xx) | AS4: 包管費 | AT4: 撥款日期(xxx-xx-xx) | AU4: 包管費 | AV4: 撥款日期(xxx-xx-xx) | AW4: 包管費 | AX4: 撥款日期(xxx-xx-xx) | AY4: 包管費 | AZ4: 撥款日期 | BA4: 包管費 | BB4: 撥款日期 | BC4: 包管費 | BD4: 撥款日期 | BE4: 包管費 | BF4: 撥款日期 | BG4: 包管費 | BH4: 撥款日期 | BI4: 包管費 | BJ4: 撥款日期 | BK4: 包管費 | BL4: 撥款日期 | BM4: 包管費 | BN4: 撥款日期 | BO4: 包管費 | BP4: 撥款日期 | BQ4: 包管費 | BR4: 撥款日期 | BS4: 包管費 | BT4: 撥款日期 | BU4: 包管費 | BV4: 撥款日期 | BW4: 包管費 | BX4: 撥款日期 | BY4: 包管費 | BZ4: 撥款日期 | CA4: 包管費 | CB4: 撥款日期 | CC4: 包管費 | CD4: 撥款日期 | CE4: 包管費 | CF4: 撥款日期 | CG4: 包管費 | CH4: 撥款日期 | CI4: 包管費 | CJ4: 撥款日期 | CK4: 包管費 | CL4: 撥款日期 | CM4: 包管費 | CN4: 撥款日期 | CO4: 包管費 | CP4: 撥款日期 | CQ4: 包管費 | CR4: 撥款日期 | CS4: 包管費 | CT4: 撥款日期 | DB4: 修繕費 | DC4: 撥款日期(xxx-xx-xx) | DD4: 修繕費 | DE4: 撥款日期(xxx-xx-xx) | DF4: 修繕費 | DG4: 撥款日期(xxx-xx-xx) | DH4: 修繕費 | DI4: 撥款日期(xxx-xx-xx) | DM4: 修繕費 | DN4: 撥款日期 | DO4: 修繕費 | DP4: 撥款日期 | DQ4: 修繕費 | DR4: 撥款日期 | DS4: 修繕費 | DT4: 撥款日期 | DX4: 修繕費 | DY4: 撥款日期 | DZ4: 修繕費 | EA4: 撥款日期 | EB4: 修繕費 | EC4: 撥款日期 | ED4: 修繕費 | EE4: 撥款日期 | EM4: 姓名 | EN4: 身分證 | EO4: 與代表人關係 | EP4: 姓名 | EQ4: 身分證 | ER4: 與代表人關係 | ES4: 姓名 | ET4: 身分證 | EU4: 與代表人關係 | FA4: 姓名 | FB4: 身分證 | FC4: 與代表人關係 | FJ4: 租金補貼 | FK4: 撥款日期(xxx-xx-xx) | FL4: 租金補貼 | FM4: 撥款日期(xxx-xx-xx) | FN4: 租金補貼 | FO4: 撥款日期(xxx-xx-xx) | FP4: 租金補貼 | FQ4: 撥款日期(xxx-xx-xx) | FR4: 租金補貼 | FS4: 撥款日期(xxx-xx-xx) | FT4: 租金補貼 | FU4: 撥款日期(xxx-xx-xx) | FV4: 租金補貼 | FW4: 撥款日期(xxx-xx-xx) | FX4: 租金補貼 | FY4: 撥款日期(xxx-xx-xx) | FZ4: 租金補貼 | GA4: 撥款日期(xxx-xx-xx) | GB4: 租金補貼 | GC4: 撥款日期(xxx-xx-xx) | GD4: 租金補貼 | GE4: 撥款日期(xxx-xx-xx) | GF4: 租金補貼 | GG4: 撥款日期(xxx-xx-xx) | GH4: 租金補貼 | GI4: 撥款日期 | GJ4: 租金補貼 | GK4: 撥款日期 | GL4: 租金補貼 | GM4: 撥款日期 | GN4: 租金補貼 | GO4: 撥款日期 | GP4: 租金補貼 | GQ4: 撥款日期 | GR4: 租金補貼 | GS4: 撥款日期 | GT4: 租金補貼 | GU4: 撥款日期 | GV4: 租金補貼 | GW4: 撥款日期 | GX4: 租金補貼 | GY4: 撥款日期 | GZ4: 租金補貼 | HA4: 撥款日期 | HB4: 租金補貼 | HC4: 撥款日期 | HD4: 租金補貼 | HE4: 撥款日期 | HF4: 租金補貼 | HG4: 撥款日期 | HH4: 租金補貼 | HI4: 撥款日期 | HJ4: 租金補貼 | HK4: 撥款日期 | HL4: 租金補貼 | HM4: 撥款日期 | HN4: 租金補貼 | HO4: 撥款日期 | HP4: 租金補貼 | HQ4: 撥款日期 | HR4: 租金補貼 | HS4: 撥款日期 | HT4: 租金補貼 | HU4: 撥款日期 | HV4: 租金補貼 | HW4: 撥款日期 | HX4: 租金補貼 | HY4: 撥款日期 | HZ4: 租金補貼 | IA4: 撥款日期 | IB4: 租金補貼 | IC4: 撥款日期
A5: =ROW()-4 -> 1 | B5: 易居 | C5: 0 | D5: 易居A2M30400102 | E5: 續約 | G5: 臺北市萬華區成都路81號10樓之14 | H5: 萬華區 | I5: 福星段 | J5: 0577-0000 | K5: 02499-000 | L5: 36.01 | M5: 全部 | N5: 113/06/05 | O5: 114/06/04 | P5: 113/06/05 | Q5: 116/06/04 | R5: 16000 | S5: 24000 | T5: 113-07-31 | U5: 3300 | V5: 113-07-31 | AA5: 4000 | AB5: 113-07-31 | AC5: 4000 | AD5: 113-09-20 | AE5: 4000 | AF5: 113-10-20 | AG5: 4000 | AH5: 113-11-20 | AI5: 4000 | AJ5: 113-12-20 | AK5: 4000 | AL5: 114-01-20 | AM5: 4000 | AN5: 114-02-20 | AO5: 4000 | AP5: 45736 | AQ5: 4000 | AR5: 114-04-20 | AS5: 4000 | AT5: 45797 | AU5: =AS5 -> 4000 | AV5: 45828 | AW5: =AU5 -> 4000 | AX5: 45858 | CU5: 許裕昌 | CV5: P120068912 | CW5: 7000021 | CX5: 00013270402720 | CY5: 臺北市大安區和平東路二段311巷43弄7號15樓 | DJ5: =10000-DH5-DF5-DD5-DB5 -> 10000 | DK5: 1330 | DL5: 113-09-20 | EI5: 周品妍 | EJ5: F230132291 | EK5: 7000021 | EL5: 24410900014196
A6: =ROW()-4 -> 2 | B6: 易居 | C6: 0 | D6: 易居A2M30400124 | E6: 中止租約 | F6: 115-05-15 | G6: 臺北市北投區西安街一段187號3樓 | H6: =MID(G6,4,3) -> 北投區 | I6: 文林段三小段 | J6: 0271-0000 | K6: 33722-000 | L6: 58.92 | M6: 全部 | N6: 113/09/15 | O6: 115/09/14 | P6: 113/09/15 | Q6: 115/09/14 | R6: 10000 | S6: =24000/4 -> 6000 | T6: 113-11-20 | U6: 3200 | V6: 113-11-20 | AA6: 4000 | AB6: 113-11-20 | AC6: 4000 | AD6: 113-12-20 | AE6: 4000 | AF6: 114-01-20 | AG6: 4000 | AH6: 114-02-20 | AI6: 4000 | AJ6: 45736 | AK6: 4000 | AL6: 114-04-20 | AM6: 4000 | AN6: 45797 | AO6: =AM6 -> 4000 | AP6: 45828 | AQ6: =AO6 -> 4000 | AR6: 45858 | AS6: =AQ6 -> 4000 | AT6: 45889 | AU6: =AS6 -> 4000 | AV6: 45920 | AW6: 4000 | AX6: 45950 | AY6: 4000 | AZ6: 45981 | BA6: 4000 | BB6: 46011 | BC6: =BA6 -> 4000 | BD6: 115-01-20 | BE6: 4000 | BF6: 115-02-26 | BG6: =BE6 -> 4000 | BH6: 115-03-20 | BI6: =BG6 -> 4000 | BJ6: 46132 | BK6: 4000 | BL6: 46162 | BM6: 4000 | BN6: 46195 | BO6: 4000 | BP6: 46223 | BQ6: - | BR6: - | BS6: - | BT6: - | BU6: - | BV6: - | BW6: - | BX6: - | BY6: - | BZ6: - | CA6: - | CB6: - | CC6: - | CD6: - | CE6: - | CF6: - | CG6: - | CH6: - | CI6: - | CJ6: - | CK6: - | CL6: - | CM6: - | CN6: - | CO6: - | CP6: - | CQ6: - | CR6: - | CS6: - | CT6: - | CU6: 陳凱倫 | CV6: A224443751 | CW6: 0124209 | CX6: 00420168168607 | CY6: 臺北市北投區石牌里7鄰西安街一段187號3樓 | DB6: 10000 | DC6: 45920 | DJ6: =10000-DH6-DF6-DD6-DB6 -> 0 | EI6: 李采庭 | EJ6: Q222595399 | EK6: 0130187 | EL6: 018505511545 | EM6: 黃國軒 | EN6: A132510465 | EO6: 長男 | EP6: 黃唯禎 | EQ6: A232090997 | ER6: 長女
A7: =ROW()-4 -> 3 | B7: 易居 | C7: 0 | D7: 易居A2M30400102-1 | G7: 臺北市萬華區成都路81號10樓之14 | H7: 萬華區 | I7: 福星段 | J7: 0577-0000 | K7: 02499-000 | L7: 36.01 | M7: 全部 | N7: 45813 | O7: =N7+364 -> 46177 | P7: 113/06/05 | Q7: 116/06/04 | R7: 16000 | S7: 6000 | T7: 45889 | U7: - | V7: - | W7: 4500 | X7: 45889 | AA7: - | AB7: - | AC7: - | AD7: - | AE7: - | AF7: - | AG7: - | AH7: - | AI7: - | AJ7: - | AK7: - | AL7: - | AM7: - | AN7: - | AO7: - | AP7: - | AQ7: - | AR7: - | AS7: - | AT7: - | AU7: - | AV7: - | AW7: - | AX7: - | AY7: 4000 | AZ7: 45889 | BA7: =AY7 -> 4000 | BB7: 45920 | BC7: 4000 | BD7: 45950 | BE7: 4000 | BF7: 45981 | BG7: 4000 | BH7: 46011 | BI7: =BG7 -> 4000 | BJ7: 115-01-20 | BK7: 4000 | BL7: 115-02-26 | BM7: =BK7 -> 4000 | BN7: 115-03-20 | BO7: =BM7 -> 4000 | BP7: 46132 | BQ7: 4000 | BR7: 46162 | BS7: 4000 | BT7: 46193 | BU7: 4000 | BV7: 46223 | BW7: 4000 | BX7: 115-08-20 | CU7: 許裕昌 | CV7: P120068912 | CW7: 7000021 | CX7: 00013270402720 | CY7: 臺北市大安區和平東路二段311巷43弄7號15樓 | DJ7: =10000-DH7-DF7-DD7-DB7 -> 10000 | DK7: 1436 | DL7: 114-09-20 | EI7: 周品妍 | EJ7: F230132291 | EK7: 7000021 | EL7: 24410900014196
D49: 各計 | S49: =SUM(S5:S48) -> 36000 | U49: =SUM(U5:U48) -> 6500 | AA49: =SUM(AA5:AA48) -> 8000 | AC49: =SUM(AC5:AC48) -> 8000 | AE49: =SUM(AE5:AE48) -> 8000 | AG49: =SUM(AG5:AG48) -> 8000 | AI49: =SUM(AI5:AI48) -> 8000 | AK49: =SUM(AK5:AK48) -> 8000 | AM49: =SUM(AM5:AM48) -> 8000 | AO49: =SUM(AO5:AO48) -> 8000 | AQ49: =SUM(AQ5:AQ48) -> 8000 | AS49: =SUM(AS5:AS48) -> 8000 | AU49: =SUM(AU5:AU48) -> 8000 | AW49: =SUM(AW5:AW48) -> 8000 | DB49: =SUM(DB5:DB48) -> 10000 | DD49: =SUM(DD5:DD48) -> 0 | DF49: =SUM(DF5:DF48) -> 0 | DH49: =SUM(DH5:DH48) -> 0 | DK49: =SUM(DK5:DK48) -> 2766 | FD49: =SUM(FD5:FD48) -> 0 | FJ49: =SUM(FJ5:FJ48) -> 0 | FL49: =SUM(FL5:FL48) -> 0 | FN49: =SUM(FN5:FN48) -> 0 | FP49: =SUM(FP5:FP48) -> 0 | FR49: =SUM(FR5:FR48) -> 0 | FT49: =SUM(FT5:FT48) -> 0 | FV49: =SUM(FV5:FV48) -> 0 | FX49: =SUM(FX5:FX48) -> 0 | FZ49: =SUM(FZ5:FZ48) -> 0 | GB49: =SUM(GB5:GB48) -> 0 | GD49: =SUM(GD5:GD48) -> 0 | GF49: =SUM(GF5:GF48) -> 0
D50: 總計 | AA50: =SUM(AA49:AX49) -> 96000 | DB50: =SUM(DB49:DH49) -> 10000 | FD50: =SUM(FD49,U49) -> 6500 | FJ50: =SUM(FJ49:GG49) -> 0
D51: 本期 | S51: =SUM(#REF!) -> #REF! | AA51: =SUM(#REF!) -> #REF! | FD51: =SUM(#REF!) -> #REF!
D52: 本期(代＋包) | FD52: =FD51+'代租 '!EU6 -> #REF! | FJ52: =FJ51+'代租 '!FA257 -> 0
